{
 "cells": [
  {
   "cell_type": "code",
   "execution_count": 10,
   "metadata": {},
   "outputs": [
    {
     "name": "stdout",
     "output_type": "stream",
     "text": [
      "Unexpected exception formatting exception. Falling back to standard exception\n"
     ]
    },
    {
     "name": "stderr",
     "output_type": "stream",
     "text": [
      "Traceback (most recent call last):\n",
      "  File \"C:\\Users\\dell\\AppData\\Roaming\\Python\\Python310\\site-packages\\IPython\\core\\interactiveshell.py\", line 3526, in run_code\n",
      "    exec(code_obj, self.user_global_ns, self.user_ns)\n",
      "  File \"C:\\Users\\dell\\AppData\\Local\\Temp\\ipykernel_18384\\236537782.py\", line -1, in <module>\n",
      "KeyboardInterrupt\n",
      "\n",
      "During handling of the above exception, another exception occurred:\n",
      "\n",
      "Traceback (most recent call last):\n",
      "  File \"C:\\Users\\dell\\AppData\\Roaming\\Python\\Python310\\site-packages\\IPython\\core\\interactiveshell.py\", line 2120, in showtraceback\n",
      "    stb = self.InteractiveTB.structured_traceback(\n",
      "  File \"C:\\Users\\dell\\AppData\\Roaming\\Python\\Python310\\site-packages\\IPython\\core\\ultratb.py\", line 1435, in structured_traceback\n",
      "    return FormattedTB.structured_traceback(\n",
      "  File \"C:\\Users\\dell\\AppData\\Roaming\\Python\\Python310\\site-packages\\IPython\\core\\ultratb.py\", line 1326, in structured_traceback\n",
      "    return VerboseTB.structured_traceback(\n",
      "  File \"C:\\Users\\dell\\AppData\\Roaming\\Python\\Python310\\site-packages\\IPython\\core\\ultratb.py\", line 1173, in structured_traceback\n",
      "    formatted_exception = self.format_exception_as_a_whole(etype, evalue, etb, number_of_lines_of_context,\n",
      "  File \"C:\\Users\\dell\\AppData\\Roaming\\Python\\Python310\\site-packages\\IPython\\core\\ultratb.py\", line 1088, in format_exception_as_a_whole\n",
      "    frames.append(self.format_record(record))\n",
      "  File \"C:\\Users\\dell\\AppData\\Roaming\\Python\\Python310\\site-packages\\IPython\\core\\ultratb.py\", line 970, in format_record\n",
      "    frame_info.lines, Colors, self.has_colors, lvals\n",
      "  File \"C:\\Users\\dell\\AppData\\Roaming\\Python\\Python310\\site-packages\\IPython\\core\\ultratb.py\", line 792, in lines\n",
      "    return self._sd.lines\n",
      "  File \"C:\\Users\\dell\\AppData\\Roaming\\Python\\Python310\\site-packages\\stack_data\\utils.py\", line 145, in cached_property_wrapper\n",
      "    value = obj.__dict__[self.func.__name__] = self.func(obj)\n",
      "  File \"C:\\Users\\dell\\AppData\\Roaming\\Python\\Python310\\site-packages\\stack_data\\core.py\", line 734, in lines\n",
      "    pieces = self.included_pieces\n",
      "  File \"C:\\Users\\dell\\AppData\\Roaming\\Python\\Python310\\site-packages\\stack_data\\utils.py\", line 145, in cached_property_wrapper\n",
      "    value = obj.__dict__[self.func.__name__] = self.func(obj)\n",
      "  File \"C:\\Users\\dell\\AppData\\Roaming\\Python\\Python310\\site-packages\\stack_data\\core.py\", line 681, in included_pieces\n",
      "    pos = scope_pieces.index(self.executing_piece)\n",
      "  File \"C:\\Users\\dell\\AppData\\Roaming\\Python\\Python310\\site-packages\\stack_data\\utils.py\", line 145, in cached_property_wrapper\n",
      "    value = obj.__dict__[self.func.__name__] = self.func(obj)\n",
      "  File \"C:\\Users\\dell\\AppData\\Roaming\\Python\\Python310\\site-packages\\stack_data\\core.py\", line 660, in executing_piece\n",
      "    return only(\n",
      "  File \"C:\\Users\\dell\\AppData\\Roaming\\Python\\Python310\\site-packages\\executing\\executing.py\", line 116, in only\n",
      "    raise NotOneValueFound('Expected one value, found 0')\n",
      "executing.executing.NotOneValueFound: Expected one value, found 0\n"
     ]
    },
    {
     "ename": "",
     "evalue": "",
     "output_type": "error",
     "traceback": [
      "\u001b[1;31m在当前单元格或上一个单元格中执行代码时 Kernel 崩溃。请查看单元格中的代码，以确定故障的可能原因。有关详细信息，请单击 <a href='https://aka.ms/vscodeJupyterKernelCrash'>此处</a>。有关更多详细信息，请查看 Jupyter <a href='command:jupyter.viewOutput'>log</a>。"
     ]
    }
   ],
   "source": [
    "i = input(\"数据集数量：\")\n",
    "i = int(i)\n",
    "\n",
    "c = []\n",
    "for a in range(i):\n",
    "    a+=1\n",
    "    for b in range(i):\n",
    "        b+=1\n",
    "        if i % (a * b) == 0:\n",
    "            if [b,a] not in c:\n",
    "                c.append([a,b])\n",
    "c"
   ]
  }
 ],
 "metadata": {
  "kernelspec": {
   "display_name": "Python 3",
   "language": "python",
   "name": "python3"
  },
  "language_info": {
   "codemirror_mode": {
    "name": "ipython",
    "version": 3
   },
   "file_extension": ".py",
   "mimetype": "text/x-python",
   "name": "python",
   "nbconvert_exporter": "python",
   "pygments_lexer": "ipython3",
   "version": "3.10.6"
  }
 },
 "nbformat": 4,
 "nbformat_minor": 2
}
